<?xml version="1.0" ?>
<!-- Generated using onshape-to-robot -->
<!-- Onshape https://cad.onshape.com/documents/eeb0103cbd40b637e0365577/w/3770feffb436f687f1e01e34/e/4b6bb467300bca03175a1b05 -->
<robot name="robot_arm_2025">
  <!-- Link v2_base_subassembly_link -->
  <link name="v2_base_subassembly_link">
    <inertial>
      <origin xyz="4.07318e-06 -0.0502911 -0.0043313" rpy="0 0 0"/>
      <mass value="1.51321"/>
      <inertia ixx="0.00316803" ixy="2.34651e-07" ixz="1.5938e-07" iyy="0.00235832" iyz="-6.0899e-05" izz="0.00372332"/>
    </inertial>
    <!-- Part v2_base_subassembly_link -->
    <visual>
      <origin xyz="0 -0.003175 0" rpy="0 -0 -1.5708"/>
      <geometry>
        <mesh filename="package://robot_arm_2025/meshes/visual/v2_base_subassembly_link.stl"/>
      </geometry>
      <material name="v2_base_subassembly_link_material">
        <color rgba="0.647059 0.647059 0.647059 1"/>
      </material>
    </visual>
    <collision>
      <origin xyz="0 -0.003175 0" rpy="0 -0 -1.5708"/>
      <geometry>
        <mesh filename="package://robot_arm_2025/meshes/collision/v2_base_subassembly_link_collision.stl"/>
      </geometry>
    </collision>
  </link>
  <!-- Link v2_j1_subassembly_link -->
  <link name="v2_j1_subassembly_link">
    <inertial>
      <origin xyz="-0.0713964 3e-12 -0.0312472" rpy="0 0 0"/>
      <mass value="3.54568"/>
      <inertia ixx="0.0118823" ixy="-5e-12" ixz="-0.00266312" iyy="0.0237233" iyz="-2.66497e-05" izz="0.0314315"/>
    </inertial>
    <!-- Part v2_j1_subassembly_link -->
    <visual>
      <origin xyz="0 -0 -0.002" rpy="-3.14159 0 0"/>
      <geometry>
        <mesh filename="package://robot_arm_2025/meshes/visual/v2_j1_subassembly_link.stl"/>
      </geometry>
      <material name="v2_j1_subassembly_link_material">
        <color rgba="0.647059 0.647059 0.647059 1"/>
      </material>
    </visual>
    <collision>
      <origin xyz="0 -0 -0.002" rpy="-3.14159 0 0"/>
      <geometry>
        <mesh filename="package://robot_arm_2025/meshes/collision/v2_j1_subassembly_link_collision.stl"/>
      </geometry>
    </collision>
  </link>
  <!-- Link v2_limb_1_subassembly_link -->
  <link name="v2_limb_1_subassembly_link">
    <inertial>
      <origin xyz="0.0923601 0.0923647 -0.0408998" rpy="0 0 0"/>
      <mass value="0.653342"/>
      <inertia ixx="0.00658938" ixy="-0.00640996" ixz="0.000302437" iyy="0.00658973" iyz="0.000302447" izz="0.0129345"/>
    </inertial>
    <!-- Part v2_limb_1_subassembly_link -->
    <visual>
      <origin xyz="0.140978 0.140978 -0.0443" rpy="1.5708 0 0.785398"/>
      <geometry>
        <mesh filename="package://robot_arm_2025/meshes/visual/v2_limb_1_subassembly_link.stl"/>
      </geometry>
      <material name="v2_limb_1_subassembly_link_material">
        <color rgba="0.647059 0.647059 0.647059 1"/>
      </material>
    </visual>
    <collision>
      <origin xyz="0.140978 0.140978 -0.0443" rpy="1.5708 0 0.785398"/>
      <geometry>
        <mesh filename="package://robot_arm_2025/meshes/collision/v2_limb_1_subassembly_link_collision.stl"/>
      </geometry>
    </collision>
  </link>
  <!-- Link v2_limb_2_subassembly_link -->
  <link name="v2_limb_2_subassembly_link">
    <inertial>
      <origin xyz="-8.66429e-05 -0.183172 -0.0171898" rpy="0 0 0"/>
      <mass value="0.468531"/>
      <inertia ixx="0.0133175" ixy="7.25101e-06" ixz="8.4204e-08" iyy="0.000101321" iyz="-0.00013504" izz="0.0133635"/>
    </inertial>
    <!-- Part v2_limb_2_subassembly_link -->
    <visual>
      <origin xyz="0 -0.179373 -0.0185" rpy="-1.5708 -0 -1.5708"/>
      <geometry>
        <mesh filename="package://robot_arm_2025/meshes/visual/v2_limb_2_subassembly_link.stl"/>
      </geometry>
      <material name="v2_limb_2_subassembly_link_material">
        <color rgba="0.647059 0.647059 0.647059 1"/>
      </material>
    </visual>
    <collision>
      <origin xyz="0 -0.179373 -0.0185" rpy="-1.5708 -0 -1.5708"/>
      <geometry>
        <mesh filename="package://robot_arm_2025/meshes/collision/v2_limb_2_subassembly_link_collision.stl"/>
      </geometry>
    </collision>
  </link>
  <!-- Link v2_j4_subassembly_link -->
  <link name="v2_j4_subassembly_link">
    <inertial>
      <origin xyz="0.0262006 -0.0426423 -0.00846426" rpy="0 0 0"/>
      <mass value="0.519744"/>
      <inertia ixx="0.000511447" ixy="5.16727e-05" ixz="-1.3572e-05" iyy="0.000338242" iyz="2.37822e-05" izz="0.000537518"/>
    </inertial>
    <!-- Part v2_j4_subassembly_link -->
    <visual>
      <origin xyz="0.0604576 -0.0604576 0" rpy="1.5708 0 -2.35619"/>
      <geometry>
        <mesh filename="package://robot_arm_2025/meshes/visual/v2_j4_subassembly_link.stl"/>
      </geometry>
      <material name="v2_j4_subassembly_link_material">
        <color rgba="0.647059 0.647059 0.647059 1"/>
      </material>
    </visual>
    <collision>
      <origin xyz="0.0604576 -0.0604576 0" rpy="1.5708 0 -2.35619"/>
      <geometry>
        <mesh filename="package://robot_arm_2025/meshes/collision/v2_j4_subassembly_link_collision.stl"/>
      </geometry>
    </collision>
  </link>
  <!-- Link v2_j5_subassembly -->
  <link name="v2_j5_subassembly">
    <inertial>
      <origin xyz="0.00187558 -0.00299972 -0.0849541" rpy="0 0 0"/>
      <mass value="0.72408"/>
      <inertia ixx="0.00207337" ixy="0.000136056" ixz="7.81862e-05" iyy="0.00232807" iyz="-7.92316e-05" izz="0.000785305"/>
    </inertial>
    <!-- Part heavy_lift_claw_subassembly_link -->
    <visual>
      <origin xyz="-0 0 -0.035" rpy="1.5708 -0 3.14159"/>
      <geometry>
        <mesh filename="package://robot_arm_2025/meshes/visual/heavy_lift_claw_subassembly_link.stl"/>
      </geometry>
      <material name="heavy_lift_claw_subassembly_link_material">
        <color rgba="0.647059 0.647059 0.647059 1"/>
      </material>
    </visual>
    <collision>
      <origin xyz="-0 0 -0.035" rpy="1.5708 -0 3.14159"/>
      <geometry>
        <mesh filename="package://robot_arm_2025/meshes/collision/heavy_lift_claw_subassembly_link_collision.stl"/>
      </geometry>
    </collision>
    <!-- Part v2_j5_a -->
    <visual>
      <origin xyz="0 0 -0.01" rpy="1.5708 -0 0"/>
      <geometry>
        <mesh filename="package://robot_arm_2025/meshes/visual/v2_j5_a.stl"/>
      </geometry>
      <material name="v2_j5_a_material">
        <color rgba="0.647059 0.647059 0.647059 1"/>
      </material>
    </visual>
    <collision>
      <origin xyz="0 0 -0.01" rpy="1.5708 -0 0"/>
      <geometry>
        <mesh filename="package://robot_arm_2025/meshes/collision/v2_j5_a_collision.stl"/>
      </geometry>
    </collision>
  </link>
  <!-- Frame Solenoid (dummy link + fixed joint) -->
  <link name="Solenoid">
    <inertial>
      <origin xyz="0 0 0" rpy="0 0 0"/>
      <mass value="1e-9"/>
      <inertia ixx="1e-9" ixy="1e-9" ixz="1e-9" iyy="1e-9" iyz="1e-9" izz="1e-9"/>
    </inertial>
  </link>
  <joint name="Solenoid_frame" type="fixed">
    <origin xyz="-0.0421343 0.0675 -0.045" rpy="1.5708 -0 3.14159"/>
    <parent link="v2_j5_subassembly"/>
    <child link="Solenoid"/>
    <axis xyz="0 0 0"/>
  </joint>
  <!-- Frame ToolEnd (dummy link + fixed joint) -->
  <link name="ToolEnd">
    <inertial>
      <origin xyz="0 0 0" rpy="0 0 0"/>
      <mass value="1e-9"/>
      <inertia ixx="1e-9" ixy="1e-9" ixz="1e-9" iyy="1e-9" iyz="1e-9" izz="1e-9"/>
    </inertial>
  </link>
  <joint name="ToolEnd_frame" type="fixed">
    <origin xyz="0 0 -0.035" rpy="3.14159 -0 0"/>
    <parent link="v2_j5_subassembly"/>
    <child link="ToolEnd"/>
    <axis xyz="0 0 0"/>
  </joint>
  <!-- Joint from v2_j4_subassembly_link to v2_j5_subassembly -->
  <joint name="J5" type="revolute">
    <origin xyz="0.0604576 -0.0604576 0" rpy="-0.785398 -1.5708 0"/>
    <parent link="v2_j4_subassembly_link"/>
    <child link="v2_j5_subassembly"/>
    <axis xyz="0 0 1"/>
    <limit effort="10" velocity="10" lower="-3.14159" upper="3.14159"/>
  </joint>
  <!-- Joint from v2_limb_2_subassembly_link to v2_j4_subassembly_link -->
  <joint name="J4" type="revolute">
    <origin xyz="0 -0.376247 -0.0185" rpy="3.14159 -0 -1.5708"/>
    <parent link="v2_limb_2_subassembly_link"/>
    <child link="v2_j4_subassembly_link"/>
    <axis xyz="0 0 1"/>
    <limit effort="10" velocity="10" lower="-0.959931" upper="2.96706"/>
  </joint>
  <!-- Joint from v2_limb_1_subassembly_link to v2_limb_2_subassembly_link -->
  <joint name="J3" type="revolute">
    <origin xyz="0.266047 0.266047 -0.0618" rpy="0 0 0.785398"/>
    <parent link="v2_limb_1_subassembly_link"/>
    <child link="v2_limb_2_subassembly_link"/>
    <axis xyz="0 0 1"/>
    <limit effort="10" velocity="10" lower="-1.22173" upper="1.22173"/>
  </joint>
  <!-- Joint from v2_j1_subassembly_link to v2_limb_1_subassembly_link -->
  <joint name="J2" type="revolute">
    <origin xyz="0 0.058 -0.077" rpy="-1.5708 0 0"/>
    <parent link="v2_j1_subassembly_link"/>
    <child link="v2_limb_1_subassembly_link"/>
    <axis xyz="0 0 1"/>
    <limit effort="10" velocity="10" lower="-0.785398" upper="0.785398"/>
  </joint>
  <!-- Joint from v2_base_subassembly_link to v2_j1_subassembly_link -->
  <joint name="J1" type="revolute">
    <origin xyz="-0 -0.0493499 0.0293499" rpy="-3.14159 -0 -1.5708"/>
    <parent link="v2_base_subassembly_link"/>
    <child link="v2_j1_subassembly_link"/>
    <axis xyz="0 0 1"/>
    <limit effort="10" velocity="10" lower="-3.14159" upper="3.14159"/>
  </joint>
</robot>
